Workbook

Sheet Dashboard
B2: HR Analytics Dashboard
B3: Workforce · Attrition · Performance · Engagement · Compliance · Attendance · Recruitment | All KPIs are live formulas over the data sheets.
B5: TOTAL EMPLOYEES | E5: ACTIVE EMPLOYEES | H5: TOTAL EXITS | K5: OVERALL ATTRITION | N5: % FEMALE | Q5: AVG CTC (ACTIVE)
B6: =COUNTA(Employees!$A$2:$A$1501) -> 1500 | E6: =COUNTIF(Employees!$U$2:$U$1501,"Active") -> 1237 | H6: =COUNTA(Attrition!$A$2:$A$264) -> 263 | K6: =COUNTA(Attrition!$A$2:$A$264)/COUNTA(Employees!$A$2:$A$1501) -> 0.17533333 | N6: =COUNTIF(Employees!$D$2:$D$1501,"Female")/COUNTA(Employees!$A$2:$A$1501) -> 0.44733333 | Q6: =AVERAGEIFS(Employees!$P$2:$P$1501,Employees!$U$2:$U$1501,"Active") -> 1962206.1
B8: AVG PERF RATING (1-5) | E8: eNPS (2026) | H8: TRAINING COMPLETION | K8: ATTENDANCE RATE | N8: AVG TIME-TO-HIRE (DAYS) | Q8: AVG COST PER HIRE
B9: =AVERAGE(Performance!$C$2:$C$3701) -> 2.7616216 | E9: =(COUNTIFS(Engagement!$B$2:$B$2375,2026,Engagement!$H$2:$H$2375,">=9")-COUNTIFS(Engagement!$B$2:$B$2375,2026,Engagement!$H$2:$H$2375,"<=6"))/COUNTIF(Engagement!$B$2:$B$2375,2026)*100 -> -1.6556291 | H9: =COUNTIF(Compliance_Trainings!$E$2:$E$7423,"Completed")/COUNTA(Compliance_Trainings!$A$2:$A$7423) -> 0.75249259 | K9: =SUM(Attendance!$D$2:$D$13892)/SUM(Attendance!$C$2:$C$13892) -> 0.92955216 | N9: =AVERAGE(Recruitment!$N$2:$N$1501) -> 53.783333 | Q9: =AVERAGE(Recruitment!$K$2:$K$1501) -> 36392.794
B68: Key Insights
B69: • Attrition: 17.5% overall (263 of 1500 employees); 82% of exits are voluntary. 'Better Compensation' is the #1 reason (62 exits, 24%).
B70: • Exits are accelerating: 91 exits in 2026 vs 53 in 2025 (+72%). Sales has the highest departmental attrition (25%).
B71: • One in three exits (33%) is a regrettable loss; only 19% received a counter-offer. Compensation is the weakest exit-interview dimension.
B72: • Performance: average rating 2.76/5; only 6.2% of reviews led to promotion. Exited employees show lower average ratings than active employees.
B73: • Engagement: 2026 eNPS is negative (-1.7); recognition and work-life balance are the lowest-rated dimensions — consistent with 'Better Compensation' and 'Work-Life Balance' as top exit reasons.
B74: • Recruitment: average time-to-hire 54 days at ₹36,393 per hire. Campus is the cheapest source (₹35,131/hire); LinkedIn is the fastest (51 days).
B75: • Compliance: 75% of mandatory trainings completed; 731 records overdue — Information Security has the largest overdue backlog.
B77: Data Notes & Caveats
B78: – 48 exits (all involuntary) have no resignation date / new-employer record — expected for terminations.
B79: – 345 requisitions show an offer date earlier than the requisition open date; time-to-offer figures should be read with caution.
B80: – 2026 performance reviews and 2026 engagement survey are partial-year; attendance covers Oct 2025 – Sep 2026 only.
... B84: Sheet Index
B85: Dashboard | E85: KPIs, charts, insights
B86: EDA_Workforce | E86: Headcount, diversity, CTC, levels, age bands, hiring trend
B87: EDA_Attrition | E87: Exits by year/reason/department/tenure, exit-interview ratings
B88: EDA_Performance | E88: Ratings, goals, promotions, hikes by year & department
B89: EDA_Engagement | E89: Satisfaction dimensions & eNPS by year & department
B90: EDA_Compliance | E90: Training status, statutory record checks, grievances
B91: EDA_Attendance | E91: Monthly presence, leave, late logins, overtime
B92: EDA_Recruitment | E92: Funnel, source effectiveness, cost & speed
B93: Departments / Employees / Attrition / Exit_Reviews / Performance / Engagement / Compliance_Trainings / Compliance_Records / Attendance / Recruitment | E93: Raw data (with helper columns)

Sheet EDA_Workforce
B2: Workforce Structure — EDA
B3: Headcount, diversity, compensation and profile breakdowns. All figures are live formulas over the Employees / Departments data sheets.
B5: 1. Headcount by Department
B6: Department | C6: Total HC | D6: Active | E6: Exited | F6: Attrition % | G6: Avg CTC (Active) | H6: Avg Age | I6: % Female | J6: HC Target | K6: Gap (Act.-Tgt.)
B7: Engineering | C7: =COUNTIF(Employees!$I$2:$I$1501,B7) -> 455 | D7: =COUNTIFS(Employees!$I$2:$I$1501,B7,Employees!$U$2:$U$1501,"Active") -> 387 | E7: =COUNTIFS(Employees!$I$2:$I$1501,B7,Employees!$U$2:$U$1501,"Exited") -> 68 | F7: =E7/C7 -> 0.14945055 | G7: =AVERAGEIFS(Employees!$P$2:$P$1501,Employees!$I$2:$I$1501,B7,Employees!$U$2:$U$1501,"Active") -> 1752082.7 | H7: =AVERAGEIF(Employees!$I$2:$I$1501,B7,Employees!$E$2:$E$1501) -> 32.041758 | I7: =COUNTIFS(Employees!$I$2:$I$1501,B7,Employees!$D$2:$D$1501,"Female")/C7 -> 0.45714286 | J7: =VLOOKUP(B7,Departments!$B$2:$E$10,4,FALSE()) -> 472 | K7: =D7-J7 -> -85
B8: Data & AI | C8: =COUNTIF(Employees!$I$2:$I$1501,B8) -> 139 | D8: =COUNTIFS(Employees!$I$2:$I$1501,B8,Employees!$U$2:$U$1501,"Active") -> 117 | E8: =COUNTIFS(Employees!$I$2:$I$1501,B8,Employees!$U$2:$U$1501,"Exited") -> 22 | F8: =E8/C8 -> 0.15827338 | G8: =AVERAGEIFS(Employees!$P$2:$P$1501,Employees!$I$2:$I$1501,B8,Employees!$U$2:$U$1501,"Active") -> 1819153.8 | H8: =AVERAGEIF(Employees!$I$2:$I$1501,B8,Employees!$E$2:$E$1501) -> 31.661871 | I8: =COUNTIFS(Employees!$I$2:$I$1501,B8,Employees!$D$2:$D$1501,"Female")/C8 -> 0.48201439 | J8: =VLOOKUP(B8,Departments!$B$2:$E$10,4,FALSE()) -> 157 | K8: =D8-J8 -> -40
B9: Sales | C9: =COUNTIF(Employees!$I$2:$I$1501,B9) -> 207 | D9: =COUNTIFS(Employees!$I$2:$I$1501,B9,Employees!$U$2:$U$1501,"Active") -> 155 | E9: =COUNTIFS(Employees!$I$2:$I$1501,B9,Employees!$U$2:$U$1501,"Exited") -> 52 | F9: =E9/C9 -> 0.25120773 | G9: =AVERAGEIFS(Employees!$P$2:$P$1501,Employees!$I$2:$I$1501,B9,Employees!$U$2:$U$1501,"Active") -> 3015941.9 | H9: =AVERAGEIF(Employees!$I$2:$I$1501,B9,Employees!$E$2:$E$1501) -> 36.15942 | I9: =COUNTIFS(Employees!$I$2:$I$1501,B9,Employees!$D$2:$D$1501,"Female")/C9 -> 0.43478261 | J9: =VLOOKUP(B9,Departments!$B$2:$E$10,4,FALSE()) -> 220 | K9: =D9-J9 -> -65
B10: Customer Support | C10: =COUNTIF(Employees!$I$2:$I$1501,B10) -> 207 | D10: =COUNTIFS(Employees!$I$2:$I$1501,B10,Employees!$U$2:$U$1501,"Active") -> 170 | E10: =COUNTIFS(Employees!$I$2:$I$1501,B10,Employees!$U$2:$U$1501,"Exited") -> 37 | F10: =E10/C10 -> 0.17874396 | G10: =AVERAGEIFS(Employees!$P$2:$P$1501,Employees!$I$2:$I$1501,B10,Employees!$U$2:$U$1501,"Active") -> 2111611.8 | H10: =AVERAGEIF(Employees!$I$2:$I$1501,B10,Employees!$E$2:$E$1501) -> 32.94686 | I10: =COUNTIFS(Employees!$I$2:$I$1501,B10,Employees!$D$2:$D$1501,"Female")/C10 -> 0.4057971 | J10: =VLOOKUP(B10,Departments!$B$2:$E$10,4,FALSE()) -> 220 | K10: =D10-J10 -> -50
B11: Operations | C11: =COUNTIF(Employees!$I$2:$I$1501,B11) -> 145 | D11: =COUNTIFS(Employees!$I$2:$I$1501,B11,Employees!$U$2:$U$1501,"Active") -> 118 | E11: =COUNTIFS(Employees!$I$2:$I$1501,B11,Employees!$U$2:$U$1501,"Exited") -> 27 | F11: =E11/C11 -> 0.1862069 | G11: =AVERAGEIFS(Employees!$P$2:$P$1501,Employees!$I$2:$I$1501,B11,Employees!$U$2:$U$1501,"Active") -> 1641432.2 | H11: =AVERAGEIF(Employees!$I$2:$I$1501,B11,Employees!$E$2:$E$1501) -> 31.041379 | I11: =COUNTIFS(Employees!$I$2:$I$1501,B11,Employees!$D$2:$D$1501,"Female")/C11 -> 0.40689655 | J11: =VLOOKUP(B11,Departments!$B$2:$E$10,4,FALSE()) -> 157 | K11: =D11-J11 -> -39
B12: Finance | C12: =COUNTIF(Employees!$I$2:$I$1501,B12) -> 97 | D12: =COUNTIFS(Employees!$I$2:$I$1501,B12,Employees!$U$2:$U$1501,"Active") -> 82 | E12: =COUNTIFS(Employees!$I$2:$I$1501,B12,Employees!$U$2:$U$1501,"Exited") -> 15 | F12: =E12/C12 -> 0.15463918 | G12: =AVERAGEIFS(Employees!$P$2:$P$1501,Employees!$I$2:$I$1501,B12,Employees!$U$2:$U$1501,"Active") -> 1906682.9 | H12: =AVERAGEIF(Employees!$I$2:$I$1501,B12,Employees!$E$2:$E$1501) -> 32.113402 | I12: =COUNTIFS(Employees!$I$2:$I$1501,B12,Employees!$D$2:$D$1501,"Female")/C12 -> 0.44329897 | J12: =VLOOKUP(B12,Departments!$B$2:$E$10,4,FALSE()) -> 94 | K12: =D12-J12 -> -12
B13: Human Resources | C13: =COUNTIF(Employees!$I$2:$I$1501,B13) -> 82 | D13: =COUNTIFS(Employees!$I$2:$I$1501,B13,Employees!$U$2:$U$1501,"Active") -> 68 | E13: =COUNTIFS(Employees!$I$2:$I$1501,B13,Employees!$U$2:$U$1501,"Exited") -> 14 | F13: =E13/C13 -> 0.17073171 | G13: =AVERAGEIFS(Employees!$P$2:$P$1501,Employees!$I$2:$I$1501,B13,Employees!$U$2:$U$1501,"Active") -> 1563235.3 | H13: =AVERAGEIF(Employees!$I$2:$I$1501,B13,Employees!$E$2:$E$1501) -> 30.231707 | I13: =COUNTIFS(Employees!$I$2:$I$1501,B13,Employees!$D$2:$D$1501,"Female")/C13 -> 0.45121951 | J13: =VLOOKUP(B13,Departments!$B$2:$E$10,4,FALSE()) -> 78 | K13: =D13-J13 -> -10
B14: Marketing | C14: =COUNTIF(Employees!$I$2:$I$1501,B14) -> 100 | D14: =COUNTIFS(Employees!$I$2:$I$1501,B14,Employees!$U$2:$U$1501,"Active") -> 82 | E14: =COUNTIFS(Employees!$I$2:$I$1501,B14,Employees!$U$2:$U$1501,"Exited") -> 18 | F14: =E14/C14 -> 0.18 | G14: =AVERAGEIFS(Employees!$P$2:$P$1501,Employees!$I$2:$I$1501,B14,Employees!$U$2:$U$1501,"Active") -> 1657634.1 | H14: =AVERAGEIF(Employees!$I$2:$I$1501,B14,Employees!$E$2:$E$1501) -> 30.32 | I14: =COUNTIFS(Employees!$I$2:$I$1501,B14,Employees!$D$2:$D$1501,"Female")/C14 -> 0.46 | J14: =VLOOKUP(B14,Departments!$B$2:$E$10,4,FALSE()) -> 94 | K14: =D14-J14 -> -12
B15: Legal & Compliance | C15: =COUNTIF(Employees!$I$2:$I$1501,B15) -> 68 | D15: =COUNTIFS(Employees!$I$2:$I$1501,B15,Employees!$U$2:$U$1501,"Active") -> 58 | E15: =COUNTIFS(Employees!$I$2:$I$1501,B15,Employees!$U$2:$U$1501,"Exited") -> 10 | F15: =E15/C15 -> 0.14705882 | G15: =AVERAGEIFS(Employees!$P$2:$P$1501,Employees!$I$2:$I$1501,B15,Employees!$U$2:$U$1501,"Active") -> 2028344.8 | H15: =AVERAGEIF(Employees!$I$2:$I$1501,B15,Employees!$E$2:$E$1501) -> 33.220588 | I15: =COUNTIFS(Employees!$I$2:$I$1501,B15,Employees!$D$2:$D$1501,"Female")/C15 -> 0.54411765 | J15: =VLOOKUP(B15,Departments!$B$2:$E$10,4,FALSE()) -> 78 | K15: =D15-J15 -> -20
B16: Total | C16: =SUM(C7:C15) -> 1500 | D16: =SUM(D7:D15) -> 1237 | E16: =SUM(E7:E15) -> 263 | F16: =E16/C16 -> 0.17533333 | G16: =AVERAGEIFS(Employees!$P$2:$P$1501,Employees!$U$2:$U$1501,"Active") -> 1962206.1 | H16: =AVERAGE(Employees!$E$2:$E$1501) -> 32.447333 | I16: =COUNTIF(Employees!$D$2:$D$1501,"Female")/C16 -> 0.44733333 | J16: =SUM(J7:J15) -> 1570 | K16: =D16-J16 -> -333
B18: 2. Job Level Mix
B19: Job Level | C19: Headcount | D19: % of Total | E19: Avg CTC | F19: Avg Age
B20: L1 | C20: =COUNTIF(Employees!$K$2:$K$1501,B20) -> 199 | D20: =C20/COUNTA(Employees!$A$2:$A$1501) -> 0.13266667 | E20: =AVERAGEIF(Employees!$K$2:$K$1501,B20,Employees!$P$2:$P$1501) -> 412909.55 | F20: =AVERAGEIF(Employees!$K$2:$K$1501,B20,Employees!$E$2:$E$1501) -> 25.231156
B21: L2 | C21: =COUNTIF(Employees!$K$2:$K$1501,B21) -> 546 | D21: =C21/COUNTA(Employees!$A$2:$A$1501) -> 0.364 | E21: =AVERAGEIF(Employees!$K$2:$K$1501,B21,Employees!$P$2:$P$1501) -> 999736.26 | F21: =AVERAGEIF(Employees!$K$2:$K$1501,B21,Employees!$E$2:$E$1501) -> 28.584249
B22: L3 | C22: =COUNTIF(Employees!$K$2:$K$1501,B22) -> 292 | D22: =C22/COUNTA(Employees!$A$2:$A$1501) -> 0.19466667 | E22: =AVERAGEIF(Employees!$K$2:$K$1501,B22,Employees!$P$2:$P$1501) -> 2015976 | F22: =AVERAGEIF(Employees!$K$2:$K$1501,B22,Employees!$E$2:$E$1501) -> 33.195205
B23: L4 | C23: =COUNTIF(Employees!$K$2:$K$1501,B23) -> 463 | D23: =C23/COUNTA(Employees!$A$2:$A$1501) -> 0.30866667 | E23: =AVERAGEIF(Employees!$K$2:$K$1501,B23,Employees!$P$2:$P$1501) -> 3651062.6 | F23: =AVERAGEIF(Employees!$K$2:$K$1501,B23,Employees!$E$2:$E$1501) -> 39.632829
B25: 3. Diversity & Profile
B26: Gender | C26: Count | D26: % of Total
B27: Female | C27: =COUNTIF(Employees!$D$2:$D$1501,B27) -> 671 | D27: =C27/COUNTA(Employees!$A$2:$A$1501) -> 0.44733333
B28: Male | C28: =COUNTIF(Employees!$D$2:$D$1501,B28) -> 824 | D28: =C28/COUNTA(Employees!$A$2:$A$1501) -> 0.54933333
B29: Other | C29: =COUNTIF(Employees!$D$2:$D$1501,B29) -> 5 | D29: =C29/COUNTA(Employees!$A$2:$A$1501) -> 0.0033333333
B32: Work Mode | C32: Count | D32: % of Total
B33: Hybrid | C33: =COUNTIF(Employees!$M$2:$M$1501,B33) -> 603 | D33: =C33/COUNTA(Employees!$A$2:$A$1501) -> 0.402
B34: Onsite | C34: =COUNTIF(Employees!$M$2:$M$1501,B34) -> 673 | D34: =C34/COUNTA(Employees!$A$2:$A$1501) -> 0.44866667
B35: Remote | C35: =COUNTIF(Employees!$M$2:$M$1501,B35) -> 224 | D35: =C35/COUNTA(Employees!$A$2:$A$1501) -> 0.14933333
B38: Employment Type | C38: Count | D38: % of Total
B39: Full-time | C39: =COUNTIF(Employees!$N$2:$N$1501,B39) -> 1324 | D39: =C39/COUNTA(Employees!$A$2:$A$1501) -> 0.88266667
B40: Contract | C40: =COUNTIF(Employees!$N$2:$N$1501,B40) -> 122 | D40: =C40/COUNTA(Employees!$A$2:$A$1501) -> 0.081333333
B41: Intern | C41: =COUNTIF(Employees!$N$2:$N$1501,B41) -> 54 | D41: =C41/COUNTA(Employees!$A$2:$A$1501) -> 0.036
B44: Education | C44: Count | D44: % of Total
B45: Bachelor's | C45: =COUNTIF(Employees!$G$2:$G$1501,B45) -> 767 | D45: =C45/COUNTA(Employees!$A$2:$A$1501) -> 0.51133333
B46: Master's | C46: =COUNTIF(Employees!$G$2:$G$1501,B46) -> 399 | D46: =C46/COUNTA(Employees!$A$2:$A$1501) -> 0.266
B47: MBA | C47: =COUNTIF(Employees!$G$2:$G$1501,B47) -> 197 | D47: =C47/COUNTA(Employees!$A$2:$A$1501) -> 0.13133333
B48: Diploma | C48: =COUNTIF(Employees!$G$2:$G$1501,B48) -> 112 | D48: =C48/COUNTA(Employees!$A$2:$A$1501) -> 0.074666667
B49: PhD | C49: =COUNTIF(Employees!$G$2:$G$1501,B49) -> 25 | D49: =C49/COUNTA(Employees!$A$2:$A$1501) -> 0.016666667
B52: Marital Status | C52: Count | D52: % of Total
...

Sheet EDA_Attrition
B2: Attrition & Exits — EDA
B3: Exit volumes, reasons, tenure profile and exit-interview signals. Live formulas over the Attrition and Exit_Reviews data sheets.
B5: 1. Exits by Year
B6: Year | C6: Total Exits | D6: Voluntary | E6: Involuntary | F6: % of Workforce
B7: 2016 | C7: =COUNTIF(Attrition!$O$2:$O$264,B7) -> 3 | D7: =COUNTIFS(Attrition!$O$2:$O$264,B7,Attrition!$D$2:$D$264,"Voluntary") -> 3 | E7: =COUNTIFS(Attrition!$O$2:$O$264,B7,Attrition!$D$2:$D$264,"Involuntary") -> 0 | F7: =C7/COUNTA(Employees!$A$2:$A$1501) -> 0.002
B8: 2017 | C8: =COUNTIF(Attrition!$O$2:$O$264,B8) -> 3 | D8: =COUNTIFS(Attrition!$O$2:$O$264,B8,Attrition!$D$2:$D$264,"Voluntary") -> 3 | E8: =COUNTIFS(Attrition!$O$2:$O$264,B8,Attrition!$D$2:$D$264,"Involuntary") -> 0 | F8: =C8/COUNTA(Employees!$A$2:$A$1501) -> 0.002
B9: 2018 | C9: =COUNTIF(Attrition!$O$2:$O$264,B9) -> 2 | D9: =COUNTIFS(Attrition!$O$2:$O$264,B9,Attrition!$D$2:$D$264,"Voluntary") -> 2 | E9: =COUNTIFS(Attrition!$O$2:$O$264,B9,Attrition!$D$2:$D$264,"Involuntary") -> 0 | F9: =C9/COUNTA(Employees!$A$2:$A$1501) -> 0.0013333333
B10: 2019 | C10: =COUNTIF(Attrition!$O$2:$O$264,B10) -> 3 | D10: =COUNTIFS(Attrition!$O$2:$O$264,B10,Attrition!$D$2:$D$264,"Voluntary") -> 2 | E10: =COUNTIFS(Attrition!$O$2:$O$264,B10,Attrition!$D$2:$D$264,"Involuntary") -> 1 | F10: =C10/COUNTA(Employees!$A$2:$A$1501) -> 0.002
B11: 2020 | C11: =COUNTIF(Attrition!$O$2:$O$264,B11) -> 5 | D11: =COUNTIFS(Attrition!$O$2:$O$264,B11,Attrition!$D$2:$D$264,"Voluntary") -> 5 | E11: =COUNTIFS(Attrition!$O$2:$O$264,B11,Attrition!$D$2:$D$264,"Involuntary") -> 0 | F11: =C11/COUNTA(Employees!$A$2:$A$1501) -> 0.0033333333
B12: 2021 | C12: =COUNTIF(Attrition!$O$2:$O$264,B12) -> 17 | D12: =COUNTIFS(Attrition!$O$2:$O$264,B12,Attrition!$D$2:$D$264,"Voluntary") -> 16 | E12: =COUNTIFS(Attrition!$O$2:$O$264,B12,Attrition!$D$2:$D$264,"Involuntary") -> 1 | F12: =C12/COUNTA(Employees!$A$2:$A$1501) -> 0.011333333
B13: 2022 | C13: =COUNTIF(Attrition!$O$2:$O$264,B13) -> 21 | D13: =COUNTIFS(Attrition!$O$2:$O$264,B13,Attrition!$D$2:$D$264,"Voluntary") -> 14 | E13: =COUNTIFS(Attrition!$O$2:$O$264,B13,Attrition!$D$2:$D$264,"Involuntary") -> 7 | F13: =C13/COUNTA(Employees!$A$2:$A$1501) -> 0.014
B14: 2023 | C14: =COUNTIF(Attrition!$O$2:$O$264,B14) -> 34 | D14: =COUNTIFS(Attrition!$O$2:$O$264,B14,Attrition!$D$2:$D$264,"Voluntary") -> 26 | E14: =COUNTIFS(Attrition!$O$2:$O$264,B14,Attrition!$D$2:$D$264,"Involuntary") -> 8 | F14: =C14/COUNTA(Employees!$A$2:$A$1501) -> 0.022666667
B15: 2024 | C15: =COUNTIF(Attrition!$O$2:$O$264,B15) -> 31 | D15: =COUNTIFS(Attrition!$O$2:$O$264,B15,Attrition!$D$2:$D$264,"Voluntary") -> 23 | E15: =COUNTIFS(Attrition!$O$2:$O$264,B15,Attrition!$D$2:$D$264,"Involuntary") -> 8 | F15: =C15/COUNTA(Employees!$A$2:$A$1501) -> 0.020666667
B16: 2025 | C16: =COUNTIF(Attrition!$O$2:$O$264,B16) -> 53 | D16: =COUNTIFS(Attrition!$O$2:$O$264,B16,Attrition!$D$2:$D$264,"Voluntary") -> 46 | E16: =COUNTIFS(Attrition!$O$2:$O$264,B16,Attrition!$D$2:$D$264,"Involuntary") -> 7 | F16: =C16/COUNTA(Employees!$A$2:$A$1501) -> 0.035333333
B17: 2026 | C17: =COUNTIF(Attrition!$O$2:$O$264,B17) -> 91 | D17: =COUNTIFS(Attrition!$O$2:$O$264,B17,Attrition!$D$2:$D$264,"Voluntary") -> 75 | E17: =COUNTIFS(Attrition!$O$2:$O$264,B17,Attrition!$D$2:$D$264,"Involuntary") -> 16 | F17: =C17/COUNTA(Employees!$A$2:$A$1501) -> 0.060666667
B19: 2. Exit Reasons (Primary)
B20: Primary Reason | C20: Exits | D20: % of Exits | E20: Avg Tenure (months) | F20: % Regrettable | G20: Avg FnF Days
B21: Better Compensation | C21: =COUNTIF(Attrition!$E$2:$E$264,B21) -> 62 | D21: =C21/COUNTA(Attrition!$A$2:$A$264) -> 0.23574144 | E21: =AVERAGEIF(Attrition!$E$2:$E$264,B21,Attrition!$H$2:$H$264) -> 29.714516 | F21: =COUNTIFS(Attrition!$E$2:$E$264,B21,Attrition!$I$2:$I$264,"Yes")/C21 -> 0.35483871 | G21: =AVERAGEIF(Attrition!$E$2:$E$264,B21,Attrition!$M$2:$M$264) -> 34.612903
B22: Career Growth | C22: =COUNTIF(Attrition!$E$2:$E$264,B22) -> 42 | D22: =C22/COUNTA(Attrition!$A$2:$A$264) -> 0.15969582 | E22: =AVERAGEIF(Attrition!$E$2:$E$264,B22,Attrition!$H$2:$H$264) -> 29.633333 | F22: =COUNTIFS(Attrition!$E$2:$E$264,B22,Attrition!$I$2:$I$264,"Yes")/C22 -> 0.42857143 | G22: =AVERAGEIF(Attrition!$E$2:$E$264,B22,Attrition!$M$2:$M$264) -> 34.904762
B23: Manager Issues | C23: =COUNTIF(Attrition!$E$2:$E$264,B23) -> 22 | D23: =C23/COUNTA(Attrition!$A$2:$A$264) -> 0.08365019 | E23: =AVERAGEIF(Attrition!$E$2:$E$264,B23,Attrition!$H$2:$H$264) -> 11.131818 | F23: =COUNTIFS(Attrition!$E$2:$E$264,B23,Attrition!$I$2:$I$264,"Yes")/C23 -> 0.36363636 | G23: =AVERAGEIF(Attrition!$E$2:$E$264,B23,Attrition!$M$2:$M$264) -> 31.681818
B24: Work-Life Balance | C24: =COUNTIF(Attrition!$E$2:$E$264,B24) -> 19 | D24: =C24/COUNTA(Attrition!$A$2:$A$264) -> 0.072243346 | E24: =AVERAGEIF(Attrition!$E$2:$E$264,B24,Attrition!$H$2:$H$264) -> 27.468421 | F24: =COUNTIFS(Attrition!$E$2:$E$264,B24,Attrition!$I$2:$I$264,"Yes")/C24 -> 0.47368421 | G24: =AVERAGEIF(Attrition!$E$2:$E$264,B24,Attrition!$M$2:$M$264) -> 35.052632
B25: Toxic Culture | C25: =COUNTIF(Attrition!$E$2:$E$264,B25) -> 19 | D25: =C25/COUNTA(Attrition!$A$2:$A$264) -> 0.072243346 | E25: =AVERAGEIF(Attrition!$E$2:$E$264,B25,Attrition!$H$2:$H$264) -> 39.021053 | F25: =COUNTIFS(Attrition!$E$2:$E$264,B25,Attrition!$I$2:$I$264,"Yes")/C25 -> 0.52631579 | G25: =AVERAGEIF(Attrition!$E$2:$E$264,B25,Attrition!$M$2:$M$264) -> 28.157895
B26: Higher Studies | C26: =COUNTIF(Attrition!$E$2:$E$264,B26) -> 17 | D26: =C26/COUNTA(Attrition!$A$2:$A$264) -> 0.064638783 | E26: =AVERAGEIF(Attrition!$E$2:$E$264,B26,Attrition!$H$2:$H$264) -> 33.182353 | F26: =COUNTIFS(Attrition!$E$2:$E$264,B26,Attrition!$I$2:$I$264,"Yes")/C26 -> 0.41176471 | G26: =AVERAGEIF(Attrition!$E$2:$E$264,B26,Attrition!$M$2:$M$264) -> 38.588235
B27: Relocation | C27: =COUNTIF(Attrition!$E$2:$E$264,B27) -> 15 | D27: =C27/COUNTA(Attrition!$A$2:$A$264) -> 0.057034221 | E27: =AVERAGEIF(Attrition!$E$2:$E$264,B27,Attrition!$H$2:$H$264) -> 13.146667 | F27: =COUNTIFS(Attrition!$E$2:$E$264,B27,Attrition!$I$2:$I$264,"Yes")/C27 -> 0.33333333 | G27: =AVERAGEIF(Attrition!$E$2:$E$264,B27,Attrition!$M$2:$M$264) -> 40.066667
B28: Performance | C28: =COUNTIF(Attrition!$E$2:$E$264,B28) -> 13 | D28: =C28/COUNTA(Attrition!$A$2:$A$264) -> 0.049429658 | E28: =AVERAGEIF(Attrition!$E$2:$E$264,B28,Attrition!$H$2:$H$264) -> 22.246154 | F28: =COUNTIFS(Attrition!$E$2:$E$264,B28,Attrition!$I$2:$I$264,"Yes")/C28 -> 0 | G28: =AVERAGEIF(Attrition!$E$2:$E$264,B28,Attrition!$M$2:$M$264) -> 33.153846
B29: Job Role Mismatch | C29: =COUNTIF(Attrition!$E$2:$E$264,B29) -> 12 | D29: =C29/COUNTA(Attrition!$A$2:$A$264) -> 0.045627376 | E29: =AVERAGEIF(Attrition!$E$2:$E$264,B29,Attrition!$H$2:$H$264) -> 19.266667 | F29: =COUNTIFS(Attrition!$E$2:$E$264,B29,Attrition!$I$2:$I$264,"Yes")/C29 -> 0.58333333 | G29: =AVERAGEIF(Attrition!$E$2:$E$264,B29,Attrition!$M$2:$M$264) -> 37
B30: Restructuring / Layoff | C30: =COUNTIF(Attrition!$E$2:$E$264,B30) -> 12 | D30: =C30/COUNTA(Attrition!$A$2:$A$264) -> 0.045627376 | E30: =AVERAGEIF(Attrition!$E$2:$E$264,B30,Attrition!$H$2:$H$264) -> 28.675 | F30: =COUNTIFS(Attrition!$E$2:$E$264,B30,Attrition!$I$2:$I$264,"Yes")/C30 -> 0 | G30: =AVERAGEIF(Attrition!$E$2:$E$264,B30,Attrition!$M$2:$M$264) -> 45
B31: Contract End | C31: =COUNTIF(Attrition!$E$2:$E$264,B31) -> 10 | D31: =C31/COUNTA(Attrition!$A$2:$A$264) -> 0.038022814 | E31: =AVERAGEIF(Attrition!$E$2:$E$264,B31,Attrition!$H$2:$H$264) -> 14.5 | F31: =COUNTIFS(Attrition!$E$2:$E$264,B31,Attrition!$I$2:$I$264,"Yes")/C31 -> 0 | G31: =AVERAGEIF(Attrition!$E$2:$E$264,B31,Attrition!$M$2:$M$264) -> 37.5
B32: Misconduct / Policy Violation | C32: =COUNTIF(Attrition!$E$2:$E$264,B32) -> 9 | D32: =C32/COUNTA(Attrition!$A$2:$A$264) -> 0.034220532 | E32: =AVERAGEIF(Attrition!$E$2:$E$264,B32,Attrition!$H$2:$H$264) -> 14.9 | F32: =COUNTIFS(Attrition!$E$2:$E$264,B32,Attrition!$I$2:$I$264,"Yes")/C32 -> 0 | G32: =AVERAGEIF(Attrition!$E$2:$E$264,B32,Attrition!$M$2:$M$264) -> 46.666667
... B34: Absconding | C34: =COUNTIF(Attrition!$E$2:$E$264,B34) -> 4 | D34: =C34/COUNTA(Attrition!$A$2:$A$264) -> 0.015209125 | E34: =AVERAGEIF(Attrition!$E$2:$E$264,B34,Attrition!$H$2:$H$264) -> 22.325 | F34: =COUNTIFS(Attrition!$E$2:$E$264,B34,Attrition!$I$2:$I$264,"Yes")/C34 -> 0 | G34: =AVERAGEIF(Attrition!$E$2:$E$264,B34,Attrition!$M$2:$M$264) -> 34.75
B36: 3. Exits by Department
B37: Department | C37: Exits | D37: Attrition % (of dept HC) | E37: % Regrettable | F37: Avg Tenure at Exit (months)
B38: Engineering | C38: =COUNTIF(Attrition!$P$2:$P$264,B38) -> 68 | D38: =C38/COUNTIF(Employees!$I$2:$I$1501,B38) -> 0.14945055 | E38: =COUNTIFS(Attrition!$P$2:$P$264,B38,Attrition!$I$2:$I$264,"Yes")/C38 -> 0.29411765 | F38: =AVERAGEIF(Attrition!$P$2:$P$264,B38,Attrition!$H$2:$H$264) -> 28.141176
B39: Data & AI | C39: =COUNTIF(Attrition!$P$2:$P$264,B39) -> 22 | D39: =C39/COUNTIF(Employees!$I$2:$I$1501,B39) -> 0.15827338 | E39: =COUNTIFS(Attrition!$P$2:$P$264,B39,Attrition!$I$2:$I$264,"Yes")/C39 -> 0.40909091 | F39: =AVERAGEIF(Attrition!$P$2:$P$264,B39,Attrition!$H$2:$H$264) -> 21.386364
B40: Sales | C40: =COUNTIF(Attrition!$P$2:$P$264,B40) -> 52 | D40: =C40/COUNTIF(Employees!$I$2:$I$1501,B40) -> 0.25120773 | E40: =COUNTIFS(Attrition!$P$2:$P$264,B40,Attrition!$I$2:$I$264,"Yes")/C40 -> 0.30769231 | F40: =AVERAGEIF(Attrition!$P$2:$P$264,B40,Attrition!$H$2:$H$264) -> 29.559615
B41: Customer Support | C41: =COUNTIF(Attrition!$P$2:$P$264,B41) -> 37 | D41: =C41/COUNTIF(Employees!$I$2:$I$1501,B41) -> 0.17874396 | E41: =COUNTIFS(Attrition!$P$2:$P$264,B41,Attrition!$I$2:$I$264,"Yes")/C41 -> 0.35135135 | F41: =AVERAGEIF(Attrition!$P$2:$P$264,B41,Attrition!$H$2:$H$264) -> 37.191892
B42: Operations | C42: =COUNTIF(Attrition!$P$2:$P$264,B42) -> 27 | D42: =C42/COUNTIF(Employees!$I$2:$I$1501,B42) -> 0.1862069 | E42: =COUNTIFS(Attrition!$P$2:$P$264,B42,Attrition!$I$2:$I$264,"Yes")/C42 -> 0.37037037 | F42: =AVERAGEIF(Attrition!$P$2:$P$264,B42,Attrition!$H$2:$H$264) -> 20.748148
B43: Finance | C43: =COUNTIF(Attrition!$P$2:$P$264,B43) -> 15 | D43: =C43/COUNTIF(Employees!$I$2:$I$1501,B43) -> 0.15463918 | E43: =COUNTIFS(Attrition!$P$2:$P$264,B43,Attrition!$I$2:$I$264,"Yes")/C43 -> 0.2 | F43: =AVERAGEIF(Attrition!$P$2:$P$264,B43,Attrition!$H$2:$H$264) -> 20.66
B44: Human Resources | C44: =COUNTIF(Attrition!$P$2:$P$264,B44) -> 14 | D44: =C44/COUNTIF(Employees!$I$2:$I$1501,B44) -> 0.17073171 | E44: =COUNTIFS(Attrition!$P$2:$P$264,B44,Attrition!$I$2:$I$264,"Yes")/C44 -> 0.5 | F44: =AVERAGEIF(Attrition!$P$2:$P$264,B44,Attrition!$H$2:$H$264) -> 18.607143
B45: Marketing | C45: =COUNTIF(Attrition!$P$2:$P$264,B45) -> 18 | D45: =C45/COUNTIF(Employees!$I$2:$I$1501,B45) -> 0.18 | E45: =COUNTIFS(Attrition!$P$2:$P$264,B45,Attrition!$I$2:$I$264,"Yes")/C45 -> 0.33333333 | F45: =AVERAGEIF(Attrition!$P$2:$P$264,B45,Attrition!$H$2:$H$264) -> 13.061111
...

Sheet EDA_Performance
B2: Performance — EDA
B3: Ratings, goal attainment, promotions and increments by review year. Live formulas over the Performance data sheet.
B5: 1. Yearly Summary
B6: Review Year | C6: Reviews | D6: Avg Rating | E6: Avg Goals % | F6: Promotions | G6: Promotion % | H6: Avg Hike % | I6: Avg Training Hrs
B7: 2021 | C7: =COUNTIF(Performance!$B$2:$B$3701,B7) -> 501 | D7: =AVERAGEIF(Performance!$B$2:$B$3701,B7,Performance!$C$2:$C$3701) -> 2.762475 | E7: =AVERAGEIF(Performance!$B$2:$B$3701,B7,Performance!$D$2:$D$3701) -> 81.083832 | F7: =COUNTIFS(Performance!$B$2:$B$3701,B7,Performance!$E$2:$E$3701,"Yes") -> 38 | G7: =F7/C7 -> 0.075848303 | H7: =AVERAGEIF(Performance!$B$2:$B$3701,B7,Performance!$F$2:$F$3701) -> 6.0902196 | I7: =AVERAGEIF(Performance!$B$2:$B$3701,B7,Performance!$G$2:$G$3701) -> 23.668663
B8: 2022 | C8: =COUNTIF(Performance!$B$2:$B$3701,B8) -> 600 | D8: =AVERAGEIF(Performance!$B$2:$B$3701,B8,Performance!$C$2:$C$3701) -> 2.705 | E8: =AVERAGEIF(Performance!$B$2:$B$3701,B8,Performance!$D$2:$D$3701) -> 81.86 | F8: =COUNTIFS(Performance!$B$2:$B$3701,B8,Performance!$E$2:$E$3701,"Yes") -> 25 | G8: =F8/C8 -> 0.041666667 | H8: =AVERAGEIF(Performance!$B$2:$B$3701,B8,Performance!$F$2:$F$3701) -> 5.9345 | I8: =AVERAGEIF(Performance!$B$2:$B$3701,B8,Performance!$G$2:$G$3701) -> 22.161667
B9: 2023 | C9: =COUNTIF(Performance!$B$2:$B$3701,B9) -> 724 | D9: =AVERAGEIF(Performance!$B$2:$B$3701,B9,Performance!$C$2:$C$3701) -> 2.7859116 | E9: =AVERAGEIF(Performance!$B$2:$B$3701,B9,Performance!$D$2:$D$3701) -> 81.918508 | F9: =COUNTIFS(Performance!$B$2:$B$3701,B9,Performance!$E$2:$E$3701,"Yes") -> 48 | G9: =F9/C9 -> 0.066298343 | H9: =AVERAGEIF(Performance!$B$2:$B$3701,B9,Performance!$F$2:$F$3701) -> 6.0799724 | I9: =AVERAGEIF(Performance!$B$2:$B$3701,B9,Performance!$G$2:$G$3701) -> 23.523481
B10: 2024 | C10: =COUNTIF(Performance!$B$2:$B$3701,B10) -> 849 | D10: =AVERAGEIF(Performance!$B$2:$B$3701,B10,Performance!$C$2:$C$3701) -> 2.7644287 | E10: =AVERAGEIF(Performance!$B$2:$B$3701,B10,Performance!$D$2:$D$3701) -> 80.941107 | F10: =COUNTIFS(Performance!$B$2:$B$3701,B10,Performance!$E$2:$E$3701,"Yes") -> 49 | G10: =F10/C10 -> 0.057714959 | H10: =AVERAGEIF(Performance!$B$2:$B$3701,B10,Performance!$F$2:$F$3701) -> 6.1744405 | I10: =AVERAGEIF(Performance!$B$2:$B$3701,B10,Performance!$G$2:$G$3701) -> 23.720848
B11: 2025 | C11: =COUNTIF(Performance!$B$2:$B$3701,B11) -> 976 | D11: =AVERAGEIF(Performance!$B$2:$B$3701,B11,Performance!$C$2:$C$3701) -> 2.8053279 | E11: =AVERAGEIF(Performance!$B$2:$B$3701,B11,Performance!$D$2:$D$3701) -> 82.145492 | F11: =COUNTIFS(Performance!$B$2:$B$3701,B11,Performance!$E$2:$E$3701,"Yes") -> 68 | G11: =F11/C11 -> 0.069672131 | H11: =AVERAGEIF(Performance!$B$2:$B$3701,B11,Performance!$F$2:$F$3701) -> 6.1010246 | I11: =AVERAGEIF(Performance!$B$2:$B$3701,B11,Performance!$G$2:$G$3701) -> 23.92623
B12: 2026 | C12: =COUNTIF(Performance!$B$2:$B$3701,B12) -> 50 | D12: =AVERAGEIF(Performance!$B$2:$B$3701,B12,Performance!$C$2:$C$3701) -> 2.18 | E12: =AVERAGEIF(Performance!$B$2:$B$3701,B12,Performance!$D$2:$D$3701) -> 78.1 | F12: =COUNTIFS(Performance!$B$2:$B$3701,B12,Performance!$E$2:$E$3701,"Yes") -> 2 | G12: =F12/C12 -> 0.04 | H12: =AVERAGEIF(Performance!$B$2:$B$3701,B12,Performance!$F$2:$F$3701) -> 4.934 | I12: =AVERAGEIF(Performance!$B$2:$B$3701,B12,Performance!$G$2:$G$3701) -> 21.74
B14: 2. Rating Distribution by Year
B15: Review Year | C15: Rating 1 | D15: Rating 2 | E15: Rating 3 | F15: Rating 4 | G15: Rating 5 | H15: Total
B16: 2021 | C16: =COUNTIFS(Performance!$B$2:$B$3701,B16,Performance!$C$2:$C$3701,1) -> 50 | D16: =COUNTIFS(Performance!$B$2:$B$3701,B16,Performance!$C$2:$C$3701,2) -> 142 | E16: =COUNTIFS(Performance!$B$2:$B$3701,B16,Performance!$C$2:$C$3701,3) -> 200 | F16: =COUNTIFS(Performance!$B$2:$B$3701,B16,Performance!$C$2:$C$3701,4) -> 95 | G16: =COUNTIFS(Performance!$B$2:$B$3701,B16,Performance!$C$2:$C$3701,5) -> 14 | H16: =SUM(C16:G16) -> 501
B17: 2022 | C17: =COUNTIFS(Performance!$B$2:$B$3701,B17,Performance!$C$2:$C$3701,1) -> 44 | D17: =COUNTIFS(Performance!$B$2:$B$3701,B17,Performance!$C$2:$C$3701,2) -> 208 | E17: =COUNTIFS(Performance!$B$2:$B$3701,B17,Performance!$C$2:$C$3701,3) -> 240 | F17: =COUNTIFS(Performance!$B$2:$B$3701,B17,Performance!$C$2:$C$3701,4) -> 97 | G17: =COUNTIFS(Performance!$B$2:$B$3701,B17,Performance!$C$2:$C$3701,5) -> 11 | H17: =SUM(C17:G17) -> 600
B18: 2023 | C18: =COUNTIFS(Performance!$B$2:$B$3701,B18,Performance!$C$2:$C$3701,1) -> 64 | D18: =COUNTIFS(Performance!$B$2:$B$3701,B18,Performance!$C$2:$C$3701,2) -> 194 | E18: =COUNTIFS(Performance!$B$2:$B$3701,B18,Performance!$C$2:$C$3701,3) -> 315 | F18: =COUNTIFS(Performance!$B$2:$B$3701,B18,Performance!$C$2:$C$3701,4) -> 135 | G18: =COUNTIFS(Performance!$B$2:$B$3701,B18,Performance!$C$2:$C$3701,5) -> 16 | H18: =SUM(C18:G18) -> 724
B19: 2024 | C19: =COUNTIFS(Performance!$B$2:$B$3701,B19,Performance!$C$2:$C$3701,1) -> 69 | D19: =COUNTIFS(Performance!$B$2:$B$3701,B19,Performance!$C$2:$C$3701,2) -> 252 | E19: =COUNTIFS(Performance!$B$2:$B$3701,B19,Performance!$C$2:$C$3701,3) -> 355 | F19: =COUNTIFS(Performance!$B$2:$B$3701,B19,Performance!$C$2:$C$3701,4) -> 156 | G19: =COUNTIFS(Performance!$B$2:$B$3701,B19,Performance!$C$2:$C$3701,5) -> 17 | H19: =SUM(C19:G19) -> 849
B20: 2025 | C20: =COUNTIFS(Performance!$B$2:$B$3701,B20,Performance!$C$2:$C$3701,1) -> 90 | D20: =COUNTIFS(Performance!$B$2:$B$3701,B20,Performance!$C$2:$C$3701,2) -> 270 | E20: =COUNTIFS(Performance!$B$2:$B$3701,B20,Performance!$C$2:$C$3701,3) -> 391 | F20: =COUNTIFS(Performance!$B$2:$B$3701,B20,Performance!$C$2:$C$3701,4) -> 190 | G20: =COUNTIFS(Performance!$B$2:$B$3701,B20,Performance!$C$2:$C$3701,5) -> 35 | H20: =SUM(C20:G20) -> 976
B21: 2026 | C21: =COUNTIFS(Performance!$B$2:$B$3701,B21,Performance!$C$2:$C$3701,1) -> 11 | D21: =COUNTIFS(Performance!$B$2:$B$3701,B21,Performance!$C$2:$C$3701,2) -> 23 | E21: =COUNTIFS(Performance!$B$2:$B$3701,B21,Performance!$C$2:$C$3701,3) -> 13 | F21: =COUNTIFS(Performance!$B$2:$B$3701,B21,Performance!$C$2:$C$3701,4) -> 2 | G21: =COUNTIFS(Performance!$B$2:$B$3701,B21,Performance!$C$2:$C$3701,5) -> 1 | H21: =SUM(C21:G21) -> 50
B23: 3. Rating by Department
B24: Department | C24: Reviews | D24: Avg Rating | E24: Promotion % | F24: Avg Hike %
B25: Engineering | C25: =COUNTIF(Performance!$H$2:$H$3701,B25) -> 1163 | D25: =AVERAGEIF(Performance!$H$2:$H$3701,B25,Performance!$C$2:$C$3701) -> 2.7815993 | E25: =COUNTIFS(Performance!$H$2:$H$3701,B25,Performance!$E$2:$E$3701,"Yes")/C25 -> 0.066208083 | F25: =AVERAGEIF(Performance!$H$2:$H$3701,B25,Performance!$F$2:$F$3701) -> 6.1067928
B26: Data & AI | C26: =COUNTIF(Performance!$H$2:$H$3701,B26) -> 312 | D26: =AVERAGEIF(Performance!$H$2:$H$3701,B26,Performance!$C$2:$C$3701) -> 2.7339744 | E26: =COUNTIFS(Performance!$H$2:$H$3701,B26,Performance!$E$2:$E$3701,"Yes")/C26 -> 0.064102564 | F26: =AVERAGEIF(Performance!$H$2:$H$3701,B26,Performance!$F$2:$F$3701) -> 5.8650641
B27: Sales | C27: =COUNTIF(Performance!$H$2:$H$3701,B27) -> 584 | D27: =AVERAGEIF(Performance!$H$2:$H$3701,B27,Performance!$C$2:$C$3701) -> 2.7089041 | E27: =COUNTIFS(Performance!$H$2:$H$3701,B27,Performance!$E$2:$E$3701,"Yes")/C27 -> 0.051369863 | F27: =AVERAGEIF(Performance!$H$2:$H$3701,B27,Performance!$F$2:$F$3701) -> 5.9717466
B28: Customer Support | C28: =COUNTIF(Performance!$H$2:$H$3701,B28) -> 517 | D28: =AVERAGEIF(Performance!$H$2:$H$3701,B28,Performance!$C$2:$C$3701) -> 2.7794971 | E28: =COUNTIFS(Performance!$H$2:$H$3701,B28,Performance!$E$2:$E$3701,"Yes")/C28 -> 0.065764023 | F28: =AVERAGEIF(Performance!$H$2:$H$3701,B28,Performance!$F$2:$F$3701) -> 6.1116054
B29: Operations | C29: =COUNTIF(Performance!$H$2:$H$3701,B29) -> 343 | D29: =AVERAGEIF(Performance!$H$2:$H$3701,B29,Performance!$C$2:$C$3701) -> 2.7609329 | E29: =COUNTIFS(Performance!$H$2:$H$3701,B29,Performance!$E$2:$E$3701,"Yes")/C29 -> 0.06122449 | F29: =AVERAGEIF(Performance!$H$2:$H$3701,B29,Performance!$F$2:$F$3701) -> 6.0451895
B30: Finance | C30: =COUNTIF(Performance!$H$2:$H$3701,B30) -> 248 | D30: =AVERAGEIF(Performance!$H$2:$H$3701,B30,Performance!$C$2:$C$3701) -> 2.8064516 | E30: =COUNTIFS(Performance!$H$2:$H$3701,B30,Performance!$E$2:$E$3701,"Yes")/C30 -> 0.064516129 | F30: =AVERAGEIF(Performance!$H$2:$H$3701,B30,Performance!$F$2:$F$3701) -> 6.1762097
B31: Human Resources | C31: =COUNTIF(Performance!$H$2:$H$3701,B31) -> 195 | D31: =AVERAGEIF(Performance!$H$2:$H$3701,B31,Performance!$C$2:$C$3701) -> 2.7487179 | E31: =COUNTIFS(Performance!$H$2:$H$3701,B31,Performance!$E$2:$E$3701,"Yes")/C31 -> 0.056410256 | F31: =AVERAGEIF(Performance!$H$2:$H$3701,B31,Performance!$F$2:$F$3701) -> 6.0061538
B32: Marketing | C32: =COUNTIF(Performance!$H$2:$H$3701,B32) -> 188 | D32: =AVERAGEIF(Performance!$H$2:$H$3701,B32,Performance!$C$2:$C$3701) -> 2.7659574 | E32: =COUNTIFS(Performance!$H$2:$H$3701,B32,Performance!$E$2:$E$3701,"Yes")/C32 -> 0.079787234 | F32: =AVERAGEIF(Performance!$H$2:$H$3701,B32,Performance!$F$2:$F$3701) -> 6.2781915
B33: Legal & Compliance | C33: =COUNTIF(Performance!$H$2:$H$3701,B33) -> 150 | D33: =AVERAGEIF(Performance!$H$2:$H$3701,B33,Performance!$C$2:$C$3701) -> 2.7466667 | E33: =COUNTIFS(Performance!$H$2:$H$3701,B33,Performance!$E$2:$E$3701,"Yes")/C33 -> 0.04 | F33: =AVERAGEIF(Performance!$H$2:$H$3701,B33,Performance!$F$2:$F$3701) -> 6.1413333
B35: 4. Active vs Exited Employees
B36: Status | C36: Reviews | D36: Avg Rating | E36: Avg Goals % | F36: Promotion %
B37: Active | C37: =COUNTIF(Performance!$I$2:$I$3701,B37) -> 3288 | D37: =AVERAGEIF(Performance!$I$2:$I$3701,B37,Performance!$C$2:$C$3701) -> 2.8062652 | E37: =AVERAGEIF(Performance!$I$2:$I$3701,B37,Performance!$D$2:$D$3701) -> 82.019161 | F37: =COUNTIFS(Performance!$I$2:$I$3701,B37,Performance!$E$2:$E$3701,"Yes")/C37 -> 0.064476886
B38: Exited | C38: =COUNTIF(Performance!$I$2:$I$3701,B38) -> 412 | D38: =AVERAGEIF(Performance!$I$2:$I$3701,B38,Performance!$C$2:$C$3701) -> 2.4053398 | E38: =AVERAGEIF(Performance!$I$2:$I$3701,B38,Performance!$D$2:$D$3701) -> 78.075243 | F38: =COUNTIFS(Performance!$I$2:$I$3701,B38,Performance!$E$2:$E$3701,"Yes")/C38 -> 0.04368932

Sheet EDA_Engagement
B2: Engagement Survey — EDA
B3: Satisfaction dimensions and eNPS by survey year and department. Live formulas over the Engagement data sheet.
B5: 1. Engagement by Survey Year
B6: Year | C6: Responses | D6: Job Sat. | E6: Environment | F6: Mgr Relation | G6: Work-Life | H6: Recognition | I6: Avg eNPS Score (0-10) | J6: % Promoters | K6: % Detractors | L6: eNPS
B7: 2024 | C7: =COUNTIF(Engagement!$B$2:$B$2375,B7) -> 679 | D7: =AVERAGEIF(Engagement!$B$2:$B$2375,B7,Engagement!$C$2:$C$2375) -> 3.4447717 | E7: =AVERAGEIF(Engagement!$B$2:$B$2375,B7,Engagement!$D$2:$D$2375) -> 3.4698085 | F7: =AVERAGEIF(Engagement!$B$2:$B$2375,B7,Engagement!$E$2:$E$2375) -> 3.4580265 | G7: =AVERAGEIF(Engagement!$B$2:$B$2375,B7,Engagement!$F$2:$F$2375) -> 3.4344624 | H7: =AVERAGEIF(Engagement!$B$2:$B$2375,B7,Engagement!$G$2:$G$2375) -> 3.4270987 | I7: =AVERAGEIF(Engagement!$B$2:$B$2375,B7,Engagement!$H$2:$H$2375) -> 7.2061856 | J7: =COUNTIFS(Engagement!$B$2:$B$2375,B7,Engagement!$H$2:$H$2375,">=9")/C7 -> 0.30486009 | K7: =COUNTIFS(Engagement!$B$2:$B$2375,B7,Engagement!$H$2:$H$2375,"<=6")/C7 -> 0.35640648 | L7: =(J7-K7)*100 -> -5.1546392
B8: 2025 | C8: =COUNTIF(Engagement!$B$2:$B$2375,B8) -> 789 | D8: =AVERAGEIF(Engagement!$B$2:$B$2375,B8,Engagement!$C$2:$C$2375) -> 3.4588086 | E8: =AVERAGEIF(Engagement!$B$2:$B$2375,B8,Engagement!$D$2:$D$2375) -> 3.4512041 | F8: =AVERAGEIF(Engagement!$B$2:$B$2375,B8,Engagement!$E$2:$E$2375) -> 3.4296578 | G8: =AVERAGEIF(Engagement!$B$2:$B$2375,B8,Engagement!$F$2:$F$2375) -> 3.4841572 | H8: =AVERAGEIF(Engagement!$B$2:$B$2375,B8,Engagement!$G$2:$G$2375) -> 3.4499366 | I8: =AVERAGEIF(Engagement!$B$2:$B$2375,B8,Engagement!$H$2:$H$2375) -> 7.2446134 | J8: =COUNTIFS(Engagement!$B$2:$B$2375,B8,Engagement!$H$2:$H$2375,">=9")/C8 -> 0.31432193 | K8: =COUNTIFS(Engagement!$B$2:$B$2375,B8,Engagement!$H$2:$H$2375,"<=6")/C8 -> 0.3409379 | L8: =(J8-K8)*100 -> -2.661597
B9: 2026 | C9: =COUNTIF(Engagement!$B$2:$B$2375,B9) -> 906 | D9: =AVERAGEIF(Engagement!$B$2:$B$2375,B9,Engagement!$C$2:$C$2375) -> 3.4569536 | E9: =AVERAGEIF(Engagement!$B$2:$B$2375,B9,Engagement!$D$2:$D$2375) -> 3.5154525 | F9: =AVERAGEIF(Engagement!$B$2:$B$2375,B9,Engagement!$E$2:$E$2375) -> 3.4238411 | G9: =AVERAGEIF(Engagement!$B$2:$B$2375,B9,Engagement!$F$2:$F$2375) -> 3.4271523 | H9: =AVERAGEIF(Engagement!$B$2:$B$2375,B9,Engagement!$G$2:$G$2375) -> 3.5110375 | I9: =AVERAGEIF(Engagement!$B$2:$B$2375,B9,Engagement!$H$2:$H$2375) -> 7.3233996 | J9: =COUNTIFS(Engagement!$B$2:$B$2375,B9,Engagement!$H$2:$H$2375,">=9")/C9 -> 0.33112583 | K9: =COUNTIFS(Engagement!$B$2:$B$2375,B9,Engagement!$H$2:$H$2375,"<=6")/C9 -> 0.34768212 | L9: =(J9-K9)*100 -> -1.6556291
B11: 2. Engagement by Department (all years)
B12: Department | C12: Responses | D12: Avg Job Sat. | E12: Avg Work-Life | F12: Avg eNPS Score | G12: eNPS
B13: Engineering | C13: =COUNTIF(Engagement!$I$2:$I$2375,B13) -> 775 | D13: =AVERAGEIF(Engagement!$I$2:$I$2375,B13,Engagement!$C$2:$C$2375) -> 3.4593548 | E13: =AVERAGEIF(Engagement!$I$2:$I$2375,B13,Engagement!$F$2:$F$2375) -> 3.4012903 | F13: =AVERAGEIF(Engagement!$I$2:$I$2375,B13,Engagement!$H$2:$H$2375) -> 7.3509677 | G13: =(COUNTIFS(Engagement!$I$2:$I$2375,B13,Engagement!$H$2:$H$2375,">=9")-COUNTIFS(Engagement!$I$2:$I$2375,B13,Engagement!$H$2:$H$2375,"<=6"))/C13*100 -> -0.77419355
B14: Data & AI | C14: =COUNTIF(Engagement!$I$2:$I$2375,B14) -> 217 | D14: =AVERAGEIF(Engagement!$I$2:$I$2375,B14,Engagement!$C$2:$C$2375) -> 3.4884793 | E14: =AVERAGEIF(Engagement!$I$2:$I$2375,B14,Engagement!$F$2:$F$2375) -> 3.4976959 | F14: =AVERAGEIF(Engagement!$I$2:$I$2375,B14,Engagement!$H$2:$H$2375) -> 6.9861751 | G14: =(COUNTIFS(Engagement!$I$2:$I$2375,B14,Engagement!$H$2:$H$2375,">=9")-COUNTIFS(Engagement!$I$2:$I$2375,B14,Engagement!$H$2:$H$2375,"<=6"))/C14*100 -> -16.589862
B15: Sales | C15: =COUNTIF(Engagement!$I$2:$I$2375,B15) -> 318 | D15: =AVERAGEIF(Engagement!$I$2:$I$2375,B15,Engagement!$C$2:$C$2375) -> 3.4402516 | E15: =AVERAGEIF(Engagement!$I$2:$I$2375,B15,Engagement!$F$2:$F$2375) -> 3.4308176 | F15: =AVERAGEIF(Engagement!$I$2:$I$2375,B15,Engagement!$H$2:$H$2375) -> 7.3867925 | G15: =(COUNTIFS(Engagement!$I$2:$I$2375,B15,Engagement!$H$2:$H$2375,">=9")-COUNTIFS(Engagement!$I$2:$I$2375,B15,Engagement!$H$2:$H$2375,"<=6"))/C15*100 -> 1.8867925
B16: Customer Support | C16: =COUNTIF(Engagement!$I$2:$I$2375,B16) -> 314 | D16: =AVERAGEIF(Engagement!$I$2:$I$2375,B16,Engagement!$C$2:$C$2375) -> 3.4522293 | E16: =AVERAGEIF(Engagement!$I$2:$I$2375,B16,Engagement!$F$2:$F$2375) -> 3.4968153 | F16: =AVERAGEIF(Engagement!$I$2:$I$2375,B16,Engagement!$H$2:$H$2375) -> 7.3025478 | G16: =(COUNTIFS(Engagement!$I$2:$I$2375,B16,Engagement!$H$2:$H$2375,">=9")-COUNTIFS(Engagement!$I$2:$I$2375,B16,Engagement!$H$2:$H$2375,"<=6"))/C16*100 -> 0.31847134
B17: Operations | C17: =COUNTIF(Engagement!$I$2:$I$2375,B17) -> 213 | D17: =AVERAGEIF(Engagement!$I$2:$I$2375,B17,Engagement!$C$2:$C$2375) -> 3.4647887 | E17: =AVERAGEIF(Engagement!$I$2:$I$2375,B17,Engagement!$F$2:$F$2375) -> 3.4553991 | F17: =AVERAGEIF(Engagement!$I$2:$I$2375,B17,Engagement!$H$2:$H$2375) -> 7.2629108 | G17: =(COUNTIFS(Engagement!$I$2:$I$2375,B17,Engagement!$H$2:$H$2375,">=9")-COUNTIFS(Engagement!$I$2:$I$2375,B17,Engagement!$H$2:$H$2375,"<=6"))/C17*100 -> -0.46948357
B18: Finance | C18: =COUNTIF(Engagement!$I$2:$I$2375,B18) -> 166 | D18: =AVERAGEIF(Engagement!$I$2:$I$2375,B18,Engagement!$C$2:$C$2375) -> 3.3855422 | E18: =AVERAGEIF(Engagement!$I$2:$I$2375,B18,Engagement!$F$2:$F$2375) -> 3.5180723 | F18: =AVERAGEIF(Engagement!$I$2:$I$2375,B18,Engagement!$H$2:$H$2375) -> 7.060241 | G18: =(COUNTIFS(Engagement!$I$2:$I$2375,B18,Engagement!$H$2:$H$2375,">=9")-COUNTIFS(Engagement!$I$2:$I$2375,B18,Engagement!$H$2:$H$2375,"<=6"))/C18*100 -> -7.8313253
B19: Human Resources | C19: =COUNTIF(Engagement!$I$2:$I$2375,B19) -> 125 | D19: =AVERAGEIF(Engagement!$I$2:$I$2375,B19,Engagement!$C$2:$C$2375) -> 3.504 | E19: =AVERAGEIF(Engagement!$I$2:$I$2375,B19,Engagement!$F$2:$F$2375) -> 3.336 | F19: =AVERAGEIF(Engagement!$I$2:$I$2375,B19,Engagement!$H$2:$H$2375) -> 7.016 | G19: =(COUNTIFS(Engagement!$I$2:$I$2375,B19,Engagement!$H$2:$H$2375,">=9")-COUNTIFS(Engagement!$I$2:$I$2375,B19,Engagement!$H$2:$H$2375,"<=6"))/C19*100 -> -15.2
B20: Marketing | C20: =COUNTIF(Engagement!$I$2:$I$2375,B20) -> 142 | D20: =AVERAGEIF(Engagement!$I$2:$I$2375,B20,Engagement!$C$2:$C$2375) -> 3.4225352 | E20: =AVERAGEIF(Engagement!$I$2:$I$2375,B20,Engagement!$F$2:$F$2375) -> 3.5 | F20: =AVERAGEIF(Engagement!$I$2:$I$2375,B20,Engagement!$H$2:$H$2375) -> 7.3661972 | G20: =(COUNTIFS(Engagement!$I$2:$I$2375,B20,Engagement!$H$2:$H$2375,">=9")-COUNTIFS(Engagement!$I$2:$I$2375,B20,Engagement!$H$2:$H$2375,"<=6"))/C20*100 -> 0.70422535
B21: Legal & Compliance | C21: =COUNTIF(Engagement!$I$2:$I$2375,B21) -> 104 | D21: =AVERAGEIF(Engagement!$I$2:$I$2375,B21,Engagement!$C$2:$C$2375) -> 3.4615385 | E21: =AVERAGEIF(Engagement!$I$2:$I$2375,B21,Engagement!$F$2:$F$2375) -> 3.5384615 | F21: =AVERAGEIF(Engagement!$I$2:$I$2375,B21,Engagement!$H$2:$H$2375) -> 7.1826923 | G21: =(COUNTIFS(Engagement!$I$2:$I$2375,B21,Engagement!$H$2:$H$2375,">=9")-COUNTIFS(Engagement!$I$2:$I$2375,B21,Engagement!$H$2:$H$2375,"<=6"))/C21*100 -> -3.8461538

Sheet EDA_Compliance
B2: Compliance — EDA
B3: Mandatory training status and employee statutory record checks. Live formulas over the Compliance_Trainings and Compliance_Records sheets.
B5: 1. Training Status by Course
B6: Course | C6: Completed | D6: In Progress | E6: Not Started | F6: Overdue | G6: Total | H6: Completion % | I6: Avg Score %
B7: POSH Awareness | C7: =COUNTIFS(Compliance_Trainings!$B$2:$B$7423,B7,Compliance_Trainings!$E$2:$E$7423,"Completed") -> 941 | D7: =COUNTIFS(Compliance_Trainings!$B$2:$B$7423,B7,Compliance_Trainings!$E$2:$E$7423,"In Progress") -> 100 | E7: =COUNTIFS(Compliance_Trainings!$B$2:$B$7423,B7,Compliance_Trainings!$E$2:$E$7423,"Not Started") -> 74 | F7: =COUNTIFS(Compliance_Trainings!$B$2:$B$7423,B7,Compliance_Trainings!$E$2:$E$7423,"Overdue") -> 122 | G7: =SUM(C7:F7) -> 1237 | H7: =C7/G7 -> 0.7607114 | I7: =AVERAGEIF(Compliance_Trainings!$B$2:$B$7423,B7,Compliance_Trainings!$G$2:$G$7423) -> 79.5983
B8: Code of Conduct | C8: =COUNTIFS(Compliance_Trainings!$B$2:$B$7423,B8,Compliance_Trainings!$E$2:$E$7423,"Completed") -> 928 | D8: =COUNTIFS(Compliance_Trainings!$B$2:$B$7423,B8,Compliance_Trainings!$E$2:$E$7423,"In Progress") -> 102 | E8: =COUNTIFS(Compliance_Trainings!$B$2:$B$7423,B8,Compliance_Trainings!$E$2:$E$7423,"Not Started") -> 93 | F8: =COUNTIFS(Compliance_Trainings!$B$2:$B$7423,B8,Compliance_Trainings!$E$2:$E$7423,"Overdue") -> 114 | G8: =SUM(C8:F8) -> 1237 | H8: =C8/G8 -> 0.7502021 | I8: =AVERAGEIF(Compliance_Trainings!$B$2:$B$7423,B8,Compliance_Trainings!$G$2:$G$7423) -> 79.532328
B9: Data Privacy & DPDP Act | C9: =COUNTIFS(Compliance_Trainings!$B$2:$B$7423,B9,Compliance_Trainings!$E$2:$E$7423,"Completed") -> 936 | D9: =COUNTIFS(Compliance_Trainings!$B$2:$B$7423,B9,Compliance_Trainings!$E$2:$E$7423,"In Progress") -> 95 | E9: =COUNTIFS(Compliance_Trainings!$B$2:$B$7423,B9,Compliance_Trainings!$E$2:$E$7423,"Not Started") -> 77 | F9: =COUNTIFS(Compliance_Trainings!$B$2:$B$7423,B9,Compliance_Trainings!$E$2:$E$7423,"Overdue") -> 129 | G9: =SUM(C9:F9) -> 1237 | H9: =C9/G9 -> 0.75666936 | I9: =AVERAGEIF(Compliance_Trainings!$B$2:$B$7423,B9,Compliance_Trainings!$G$2:$G$7423) -> 79.646368
B10: Information Security | C10: =COUNTIFS(Compliance_Trainings!$B$2:$B$7423,B10,Compliance_Trainings!$E$2:$E$7423,"Completed") -> 922 | D10: =COUNTIFS(Compliance_Trainings!$B$2:$B$7423,B10,Compliance_Trainings!$E$2:$E$7423,"In Progress") -> 100 | E10: =COUNTIFS(Compliance_Trainings!$B$2:$B$7423,B10,Compliance_Trainings!$E$2:$E$7423,"Not Started") -> 91 | F10: =COUNTIFS(Compliance_Trainings!$B$2:$B$7423,B10,Compliance_Trainings!$E$2:$E$7423,"Overdue") -> 124 | G10: =SUM(C10:F10) -> 1237 | H10: =C10/G10 -> 0.74535166 | I10: =AVERAGEIF(Compliance_Trainings!$B$2:$B$7423,B10,Compliance_Trainings!$G$2:$G$7423) -> 79.229935
B11: Anti-Bribery | C11: =COUNTIFS(Compliance_Trainings!$B$2:$B$7423,B11,Compliance_Trainings!$E$2:$E$7423,"Completed") -> 909 | D11: =COUNTIFS(Compliance_Trainings!$B$2:$B$7423,B11,Compliance_Trainings!$E$2:$E$7423,"In Progress") -> 98 | E11: =COUNTIFS(Compliance_Trainings!$B$2:$B$7423,B11,Compliance_Trainings!$E$2:$E$7423,"Not Started") -> 96 | F11: =COUNTIFS(Compliance_Trainings!$B$2:$B$7423,B11,Compliance_Trainings!$E$2:$E$7423,"Overdue") -> 134 | G11: =SUM(C11:F11) -> 1237 | H11: =C11/G11 -> 0.73484236 | I11: =AVERAGEIF(Compliance_Trainings!$B$2:$B$7423,B11,Compliance_Trainings!$G$2:$G$7423) -> 79.574257
B12: Fire & Safety | C12: =COUNTIFS(Compliance_Trainings!$B$2:$B$7423,B12,Compliance_Trainings!$E$2:$E$7423,"Completed") -> 949 | D12: =COUNTIFS(Compliance_Trainings!$B$2:$B$7423,B12,Compliance_Trainings!$E$2:$E$7423,"In Progress") -> 95 | E12: =COUNTIFS(Compliance_Trainings!$B$2:$B$7423,B12,Compliance_Trainings!$E$2:$E$7423,"Not Started") -> 85 | F12: =COUNTIFS(Compliance_Trainings!$B$2:$B$7423,B12,Compliance_Trainings!$E$2:$E$7423,"Overdue") -> 108 | G12: =SUM(C12:F12) -> 1237 | H12: =C12/G12 -> 0.76717866 | I12: =AVERAGEIF(Compliance_Trainings!$B$2:$B$7423,B12,Compliance_Trainings!$G$2:$G$7423) -> 80.134879
B13: Total | C13: =SUM(C7:C12) -> 5585 | D13: =SUM(D7:D12) -> 590 | E13: =SUM(E7:E12) -> 516 | F13: =SUM(F7:F12) -> 731 | G13: =SUM(G7:G12) -> 7422 | H13: =C13/G13 -> 0.75249259 | I13: =AVERAGE(Compliance_Trainings!$G$2:$G$7423) -> 79.621844
B15: 2. Statutory & Policy Record Checks (1,500 employees)
B16: Check | C16: Employees | D16: % of Workforce
B17: Background verification cleared | C17: =COUNTIF(Compliance_Records!$B$2:$B$1501,"Cleared") -> 1356 | D17: =C17/COUNTA(Compliance_Records!$A$2:$A$1501) -> 0.904
B18: PF UAN linked | C18: =COUNTIF(Compliance_Records!$C$2:$C$1501,"Yes") -> 1420 | D18: =C18/COUNTA(Compliance_Records!$A$2:$A$1501) -> 0.94666667
B19: ESI applicable | C19: =COUNTIF(Compliance_Records!$D$2:$D$1501,"Yes") -> 0 | D19: =C19/COUNTA(Compliance_Records!$A$2:$A$1501) -> 0
B20: NDA signed | C20: =COUNTIF(Compliance_Records!$E$2:$E$1501,"Yes") -> 1443 | D20: =C20/COUNTA(Compliance_Records!$A$2:$A$1501) -> 0.962
B21: Policy acknowledged | C21: =COUNTIF(Compliance_Records!$F$2:$F$1501,"Yes") -> 1374 | D21: =C21/COUNTA(Compliance_Records!$A$2:$A$1501) -> 0.916
B23: 3. Grievances & Disciplinary
B24: Metric | C24: Count
B25: Total grievances raised | C25: =SUM(Compliance_Records!$G$2:$G$1501) -> 220
B26: Employees with >=1 grievance | C26: =COUNTIF(Compliance_Records!$G$2:$G$1501,">=1") -> 208
B27: Total POSH complaints | C27: =SUM(Compliance_Records!$H$2:$H$1501) -> 18
B28: Total disciplinary actions | C28: =SUM(Compliance_Records!$I$2:$I$1501) -> 72
B29: Employees with >=1 disciplinary action | C29: =COUNTIF(Compliance_Records!$I$2:$I$1501,">=1") -> 72

Sheet EDA_Attendance
B2: Attendance & Leave — EDA
B3: Monthly presence, leave usage, late logins and overtime (Oct 2025 – Sep 2026). Live formulas over the Attendance data sheet.
B5: 1. Monthly Summary
B6: Month | C6: Emp-Months | D6: Working Days | E6: Days Present | F6: Attendance % | G6: Sick Leave | H6: Casual Leave | I6: Unplanned Abs. | J6: Late Logins | K6: Overtime Hrs | L6: OT per Emp-Month
B7: 2025-10 | C7: =COUNTIF(Attendance!$B$2:$B$13892,B7) -> 1081 | D7: =SUMIF(Attendance!$B$2:$B$13892,B7,Attendance!$C$2:$C$13892) -> 23782 | E7: =SUMIF(Attendance!$B$2:$B$13892,B7,Attendance!$D$2:$D$13892) -> 22087 | F7: =E7/D7 -> 0.92872761 | G7: =SUMIF(Attendance!$B$2:$B$13892,B7,Attendance!$E$2:$E$13892) -> 655 | H7: =SUMIF(Attendance!$B$2:$B$13892,B7,Attendance!$F$2:$F$13892) -> 742 | I7: =SUMIF(Attendance!$B$2:$B$13892,B7,Attendance!$G$2:$G$13892) -> 363 | J7: =SUMIF(Attendance!$B$2:$B$13892,B7,Attendance!$H$2:$H$13892) -> 1634 | K7: =SUMIF(Attendance!$B$2:$B$13892,B7,Attendance!$I$2:$I$13892) -> 4513 | L7: =K7/C7 -> 4.1748381
B8: 2025-11 | C8: =COUNTIF(Attendance!$B$2:$B$13892,B8) -> 1096 | D8: =SUMIF(Attendance!$B$2:$B$13892,B8,Attendance!$C$2:$C$13892) -> 24112 | E8: =SUMIF(Attendance!$B$2:$B$13892,B8,Attendance!$D$2:$D$13892) -> 22469 | F8: =E8/D8 -> 0.93185965 | G8: =SUMIF(Attendance!$B$2:$B$13892,B8,Attendance!$E$2:$E$13892) -> 696 | H8: =SUMIF(Attendance!$B$2:$B$13892,B8,Attendance!$F$2:$F$13892) -> 755 | I8: =SUMIF(Attendance!$B$2:$B$13892,B8,Attendance!$G$2:$G$13892) -> 353 | J8: =SUMIF(Attendance!$B$2:$B$13892,B8,Attendance!$H$2:$H$13892) -> 1660 | K8: =SUMIF(Attendance!$B$2:$B$13892,B8,Attendance!$I$2:$I$13892) -> 4542 | L8: =K8/C8 -> 4.1441606
B9: 2025-12 | C9: =COUNTIF(Attendance!$B$2:$B$13892,B9) -> 1106 | D9: =SUMIF(Attendance!$B$2:$B$13892,B9,Attendance!$C$2:$C$13892) -> 24332 | E9: =SUMIF(Attendance!$B$2:$B$13892,B9,Attendance!$D$2:$D$13892) -> 22610 | F9: =E9/D9 -> 0.929229 | G9: =SUMIF(Attendance!$B$2:$B$13892,B9,Attendance!$E$2:$E$13892) -> 722 | H9: =SUMIF(Attendance!$B$2:$B$13892,B9,Attendance!$F$2:$F$13892) -> 741 | I9: =SUMIF(Attendance!$B$2:$B$13892,B9,Attendance!$G$2:$G$13892) -> 349 | J9: =SUMIF(Attendance!$B$2:$B$13892,B9,Attendance!$H$2:$H$13892) -> 1654 | K9: =SUMIF(Attendance!$B$2:$B$13892,B9,Attendance!$I$2:$I$13892) -> 4864 | L9: =K9/C9 -> 4.39783
B10: 2026-01 | C10: =COUNTIF(Attendance!$B$2:$B$13892,B10) -> 1125 | D10: =SUMIF(Attendance!$B$2:$B$13892,B10,Attendance!$C$2:$C$13892) -> 24750 | E10: =SUMIF(Attendance!$B$2:$B$13892,B10,Attendance!$D$2:$D$13892) -> 23031 | F10: =E10/D10 -> 0.93054545 | G10: =SUMIF(Attendance!$B$2:$B$13892,B10,Attendance!$E$2:$E$13892) -> 703 | H10: =SUMIF(Attendance!$B$2:$B$13892,B10,Attendance!$F$2:$F$13892) -> 762 | I10: =SUMIF(Attendance!$B$2:$B$13892,B10,Attendance!$G$2:$G$13892) -> 357 | J10: =SUMIF(Attendance!$B$2:$B$13892,B10,Attendance!$H$2:$H$13892) -> 1644 | K10: =SUMIF(Attendance!$B$2:$B$13892,B10,Attendance!$I$2:$I$13892) -> 4715 | L10: =K10/C10 -> 4.1911111
B11: 2026-02 | C11: =COUNTIF(Attendance!$B$2:$B$13892,B11) -> 1142 | D11: =SUMIF(Attendance!$B$2:$B$13892,B11,Attendance!$C$2:$C$13892) -> 25124 | E11: =SUMIF(Attendance!$B$2:$B$13892,B11,Attendance!$D$2:$D$13892) -> 23290 | F11: =E11/D11 -> 0.92700207 | G11: =SUMIF(Attendance!$B$2:$B$13892,B11,Attendance!$E$2:$E$13892) -> 690 | H11: =SUMIF(Attendance!$B$2:$B$13892,B11,Attendance!$F$2:$F$13892) -> 801 | I11: =SUMIF(Attendance!$B$2:$B$13892,B11,Attendance!$G$2:$G$13892) -> 380 | J11: =SUMIF(Attendance!$B$2:$B$13892,B11,Attendance!$H$2:$H$13892) -> 1722 | K11: =SUMIF(Attendance!$B$2:$B$13892,B11,Attendance!$I$2:$I$13892) -> 5205 | L11: =K11/C11 -> 4.5577933
B12: 2026-03 | C12: =COUNTIF(Attendance!$B$2:$B$13892,B12) -> 1158 | D12: =SUMIF(Attendance!$B$2:$B$13892,B12,Attendance!$C$2:$C$13892) -> 25476 | E12: =SUMIF(Attendance!$B$2:$B$13892,B12,Attendance!$D$2:$D$13892) -> 23691 | F12: =E12/D12 -> 0.92993406 | G12: =SUMIF(Attendance!$B$2:$B$13892,B12,Attendance!$E$2:$E$13892) -> 698 | H12: =SUMIF(Attendance!$B$2:$B$13892,B12,Attendance!$F$2:$F$13892) -> 821 | I12: =SUMIF(Attendance!$B$2:$B$13892,B12,Attendance!$G$2:$G$13892) -> 385 | J12: =SUMIF(Attendance!$B$2:$B$13892,B12,Attendance!$H$2:$H$13892) -> 1716 | K12: =SUMIF(Attendance!$B$2:$B$13892,B12,Attendance!$I$2:$I$13892) -> 4752 | L12: =K12/C12 -> 4.1036269
B13: 2026-04 | C13: =COUNTIF(Attendance!$B$2:$B$13892,B13) -> 1165 | D13: =SUMIF(Attendance!$B$2:$B$13892,B13,Attendance!$C$2:$C$13892) -> 25630 | E13: =SUMIF(Attendance!$B$2:$B$13892,B13,Attendance!$D$2:$D$13892) -> 23832 | F13: =E13/D13 -> 0.92984783 | G13: =SUMIF(Attendance!$B$2:$B$13892,B13,Attendance!$E$2:$E$13892) -> 720 | H13: =SUMIF(Attendance!$B$2:$B$13892,B13,Attendance!$F$2:$F$13892) -> 891 | I13: =SUMIF(Attendance!$B$2:$B$13892,B13,Attendance!$G$2:$G$13892) -> 421 | J13: =SUMIF(Attendance!$B$2:$B$13892,B13,Attendance!$H$2:$H$13892) -> 1749 | K13: =SUMIF(Attendance!$B$2:$B$13892,B13,Attendance!$I$2:$I$13892) -> 5251 | L13: =K13/C13 -> 4.5072961
B14: 2026-05 | C14: =COUNTIF(Attendance!$B$2:$B$13892,B14) -> 1178 | D14: =SUMIF(Attendance!$B$2:$B$13892,B14,Attendance!$C$2:$C$13892) -> 25916 | E14: =SUMIF(Attendance!$B$2:$B$13892,B14,Attendance!$D$2:$D$13892) -> 23992 | F14: =E14/D14 -> 0.92576015 | G14: =SUMIF(Attendance!$B$2:$B$13892,B14,Attendance!$E$2:$E$13892) -> 740 | H14: =SUMIF(Attendance!$B$2:$B$13892,B14,Attendance!$F$2:$F$13892) -> 878 | I14: =SUMIF(Attendance!$B$2:$B$13892,B14,Attendance!$G$2:$G$13892) -> 349 | J14: =SUMIF(Attendance!$B$2:$B$13892,B14,Attendance!$H$2:$H$13892) -> 1863 | K14: =SUMIF(Attendance!$B$2:$B$13892,B14,Attendance!$I$2:$I$13892) -> 5099 | L14: =K14/C14 -> 4.3285229
B15: 2026-06 | C15: =COUNTIF(Attendance!$B$2:$B$13892,B15) -> 1184 | D15: =SUMIF(Attendance!$B$2:$B$13892,B15,Attendance!$C$2:$C$13892) -> 26048 | E15: =SUMIF(Attendance!$B$2:$B$13892,B15,Attendance!$D$2:$D$13892) -> 24214 | F15: =E15/D15 -> 0.92959152 | G15: =SUMIF(Attendance!$B$2:$B$13892,B15,Attendance!$E$2:$E$13892) -> 733 | H15: =SUMIF(Attendance!$B$2:$B$13892,B15,Attendance!$F$2:$F$13892) -> 818 | I15: =SUMIF(Attendance!$B$2:$B$13892,B15,Attendance!$G$2:$G$13892) -> 367 | J15: =SUMIF(Attendance!$B$2:$B$13892,B15,Attendance!$H$2:$H$13892) -> 1761 | K15: =SUMIF(Attendance!$B$2:$B$13892,B15,Attendance!$I$2:$I$13892) -> 5312 | L15: =K15/C15 -> 4.4864865
B16: 2026-07 | C16: =COUNTIF(Attendance!$B$2:$B$13892,B16) -> 1189 | D16: =SUMIF(Attendance!$B$2:$B$13892,B16,Attendance!$C$2:$C$13892) -> 26158 | E16: =SUMIF(Attendance!$B$2:$B$13892,B16,Attendance!$D$2:$D$13892) -> 24303 | F16: =E16/D16 -> 0.92908479 | G16: =SUMIF(Attendance!$B$2:$B$13892,B16,Attendance!$E$2:$E$13892) -> 704 | H16: =SUMIF(Attendance!$B$2:$B$13892,B16,Attendance!$F$2:$F$13892) -> 889 | I16: =SUMIF(Attendance!$B$2:$B$13892,B16,Attendance!$G$2:$G$13892) -> 395 | J16: =SUMIF(Attendance!$B$2:$B$13892,B16,Attendance!$H$2:$H$13892) -> 1761 | K16: =SUMIF(Attendance!$B$2:$B$13892,B16,Attendance!$I$2:$I$13892) -> 4964 | L16: =K16/C16 -> 4.1749369
B17: 2026-08 | C17: =COUNTIF(Attendance!$B$2:$B$13892,B17) -> 1197 | D17: =SUMIF(Attendance!$B$2:$B$13892,B17,Attendance!$C$2:$C$13892) -> 26334 | E17: =SUMIF(Attendance!$B$2:$B$13892,B17,Attendance!$D$2:$D$13892) -> 24543 | F17: =E17/D17 -> 0.93198906 | G17: =SUMIF(Attendance!$B$2:$B$13892,B17,Attendance!$E$2:$E$13892) -> 776 | H17: =SUMIF(Attendance!$B$2:$B$13892,B17,Attendance!$F$2:$F$13892) -> 810 | I17: =SUMIF(Attendance!$B$2:$B$13892,B17,Attendance!$G$2:$G$13892) -> 378 | J17: =SUMIF(Attendance!$B$2:$B$13892,B17,Attendance!$H$2:$H$13892) -> 1701 | K17: =SUMIF(Attendance!$B$2:$B$13892,B17,Attendance!$I$2:$I$13892) -> 5197 | L17: =K17/C17 -> 4.3416876
B18: 2026-09 | C18: =COUNTIF(Attendance!$B$2:$B$13892,B18) -> 1270 | D18: =SUMIF(Attendance!$B$2:$B$13892,B18,Attendance!$C$2:$C$13892) -> 27940 | E18: =SUMIF(Attendance!$B$2:$B$13892,B18,Attendance!$D$2:$D$13892) -> 26011 | F18: =E18/D18 -> 0.9309592 | G18: =SUMIF(Attendance!$B$2:$B$13892,B18,Attendance!$E$2:$E$13892) -> 751 | H18: =SUMIF(Attendance!$B$2:$B$13892,B18,Attendance!$F$2:$F$13892) -> 864 | I18: =SUMIF(Attendance!$B$2:$B$13892,B18,Attendance!$G$2:$G$13892) -> 409 | J18: =SUMIF(Attendance!$B$2:$B$13892,B18,Attendance!$H$2:$H$13892) -> 1904 | K18: =SUMIF(Attendance!$B$2:$B$13892,B18,Attendance!$I$2:$I$13892) -> 5532 | L18: =K18/C18 -> 4.3559055
B19: Total | C19: =SUM(C7:C18) -> 13891 | D19: =SUM(D7:D18) -> 305602 | E19: =SUM(E7:E18) -> 284073 | F19: =E19/D19 -> 0.92955216 | G19: =SUM(G7:G18) -> 8588 | H19: =SUM(H7:H18) -> 9772 | I19: =SUM(I7:I18) -> 4506 | J19: =SUM(J7:J18) -> 20769 | K19: =SUM(K7:K18) -> 59946 | L19: =K19/C19 -> 4.3154561
B21: 2. Key Indicators (12-month window)
B22: Indicator | C22: Value
B23: Overall attendance rate | C23: =SUM(Attendance!$D$2:$D$13892)/SUM(Attendance!$C$2:$C$13892) -> 0.92955216
B24: Total sick leave days | C24: =SUM(Attendance!$E$2:$E$13892) -> 8588
B25: Total casual leave days | C25: =SUM(Attendance!$F$2:$F$13892) -> 9772
B26: Total unplanned absences | C26: =SUM(Attendance!$G$2:$G$13892) -> 4506
B27: Total late logins | C27: =SUM(Attendance!$H$2:$H$13892) -> 20769
B28: Avg late logins per emp-month | C28: =SUM(Attendance!$H$2:$H$13892)/COUNTA(Attendance!$A$2:$A$13892) -> 1.4951407
B29: Total overtime hours | C29: =SUM(Attendance!$I$2:$I$13892) -> 59946
B30: Avg overtime hrs per emp-month | C30: =SUM(Attendance!$I$2:$I$13892)/COUNTA(Attendance!$A$2:$A$13892) -> 4.3154561

Sheet EDA_Recruitment
B2: Recruitment — EDA
B3: Hiring funnel, source effectiveness, cost and speed. Live formulas over the Recruitment data sheet.
B5: 1. Overall Funnel
B6: Funnel Stage | C6: Volume | D6: Step Conversion
B7: Applicants | C7: =SUM(Recruitment!$H$2:$H$1501) -> 112455
B8: Interviews | C8: =SUM(Recruitment!$I$2:$I$1501) -> 12756 | D8: =C8/C7 -> 0.11343204
B9: Offers Made | C9: =SUM(Recruitment!$J$2:$J$1501) -> 2422 | D9: =C9/C8 -> 0.18987143
B10: Hires (requisitions closed) | C10: =COUNTA(Recruitment!$A$2:$A$1501) -> 1500 | D10: =C10/C9 -> 0.61932287
B12: 2. Source Effectiveness
B13: Source | C13: Hires | D13: Applicants | E13: Interviews | F13: Offers | G13: Offers per Hire | H13: Applicants per Hire | I13: Avg Cost/Hire | J13: Avg Time-to-Offer (d) | K13: Avg Time-to-Hire (d) | L13: Total Spend
B14: Job Portal | C14: =COUNTIF(Recruitment!$L$2:$L$1501,B14) -> 430 | D14: =SUMIF(Recruitment!$L$2:$L$1501,B14,Recruitment!$H$2:$H$1501) -> 32431 | E14: =SUMIF(Recruitment!$L$2:$L$1501,B14,Recruitment!$I$2:$I$1501) -> 3650 | F14: =SUMIF(Recruitment!$L$2:$L$1501,B14,Recruitment!$J$2:$J$1501) -> 687 | G14: =F14/C14 -> 1.5976744 | H14: =D14/C14 -> 75.42093 | I14: =AVERAGEIF(Recruitment!$L$2:$L$1501,B14,Recruitment!$K$2:$K$1501) -> 37145.986 | J14: =AVERAGEIF(Recruitment!$L$2:$L$1501,B14,Recruitment!$M$2:$M$1501) -> 18.295349 | K14: =AVERAGEIF(Recruitment!$L$2:$L$1501,B14,Recruitment!$N$2:$N$1501) -> 55.260465 | L14: =SUMIF(Recruitment!$L$2:$L$1501,B14,Recruitment!$K$2:$K$1501) -> 15972774
B15: Referral | C15: =COUNTIF(Recruitment!$L$2:$L$1501,B15) -> 400 | D15: =SUMIF(Recruitment!$L$2:$L$1501,B15,Recruitment!$H$2:$H$1501) -> 30247 | E15: =SUMIF(Recruitment!$L$2:$L$1501,B15,Recruitment!$I$2:$I$1501) -> 3409 | F15: =SUMIF(Recruitment!$L$2:$L$1501,B15,Recruitment!$J$2:$J$1501) -> 654 | G15: =F15/C15 -> 1.635 | H15: =D15/C15 -> 75.6175 | I15: =AVERAGEIF(Recruitment!$L$2:$L$1501,B15,Recruitment!$K$2:$K$1501) -> 35703.518 | J15: =AVERAGEIF(Recruitment!$L$2:$L$1501,B15,Recruitment!$M$2:$M$1501) -> 16.825 | K15: =AVERAGEIF(Recruitment!$L$2:$L$1501,B15,Recruitment!$N$2:$N$1501) -> 54.125 | L15: =SUMIF(Recruitment!$L$2:$L$1501,B15,Recruitment!$K$2:$K$1501) -> 14281407
B16: LinkedIn | C16: =COUNTIF(Recruitment!$L$2:$L$1501,B16) -> 293 | D16: =SUMIF(Recruitment!$L$2:$L$1501,B16,Recruitment!$H$2:$H$1501) -> 21030 | E16: =SUMIF(Recruitment!$L$2:$L$1501,B16,Recruitment!$I$2:$I$1501) -> 2571 | F16: =SUMIF(Recruitment!$L$2:$L$1501,B16,Recruitment!$J$2:$J$1501) -> 472 | G16: =F16/C16 -> 1.6109215 | H16: =D16/C16 -> 71.774744 | I16: =AVERAGEIF(Recruitment!$L$2:$L$1501,B16,Recruitment!$K$2:$K$1501) -> 37297.553 | J16: =AVERAGEIF(Recruitment!$L$2:$L$1501,B16,Recruitment!$M$2:$M$1501) -> 15.300341 | K16: =AVERAGEIF(Recruitment!$L$2:$L$1501,B16,Recruitment!$N$2:$N$1501) -> 51.488055 | L16: =SUMIF(Recruitment!$L$2:$L$1501,B16,Recruitment!$K$2:$K$1501) -> 10928183
